<?xml version="1.0" ?>

<robot name="robot">
    <!-- Link - base -->
    <link name="link_base">
        <inertial>
            <mass value="22" />
            <origin xyz="0 0 0.3" rpy="0 0 0" />
            <inertia ixx="0.50875" ixy="0" ixz="0" iyy="0.50875" iyz="0" izz="0.6875" />
        </inertial>

        <collision>
            <geometry>
                <cylinder length="0.3" radius="0.25" />
            </geometry>
        </collision>

        <visual>
            <geometry>
                <cylinder length="0.3" radius="0.25" />
                <!-- <box size="2 1.3 0.4" /> -->
            </geometry>
            <material name="DarkBlue">
                <color rgba="0.2 0.2 0.4 1" />
            </material>
        </visual>
    </link>

    <!-- Joint - front caster -->
    <joint name="joint_base_front_caster" type="fixed">
        <origin rpy="0 0 0" xyz="0.2 0 -0.15" />
        <child link="link_front_caster" />
        <parent link="link_base" />
        <joint_properties damping="1.0" friction="0.0" />
    </joint>
    <!-- Link - front caster -->
    <link name="link_front_caster">
        <inertial>
            <mass value="0.5" />
            <origin xyz="0 0 0" rpy="0 0 0" />
            <inertia ixx="0.000125" ixy="0" ixz="0" iyy="0.000125" iyz="0" izz="0.000125"/>
        </inertial>
        <!-- Front caster support -->
        <collision>
            <!-- <origin rpy="0 0 0" xyz="0.1 0 -0.15" /> -->
            <origin rpy="0 0 0" xyz="0 0 -0" />
            <geometry>
                <sphere radius="0.025" />
            </geometry>
        </collision>
        <visual>
            <!-- <origin rpy="0 0 0" xyz="0.1 0 -0.15" /> -->
            <origin rpy="0 0 0" xyz="0 0 -0" />
            <geometry>
                <sphere radius="0.025" />
            </geometry>
            <material name="DarkBlue">
                <color rgba="0.2 0.2 0.4 1" />
            </material>
        </visual>
        <!-- Front caster -->
        <collision>
            <!-- <origin rpy="0 0 0" xyz="0.1 0 -0.15" /> -->
            <origin rpy="0 0 0" xyz="0 0 -0" />
            <geometry>
                <sphere radius="0.025" />
            </geometry>
        </collision>
        <visual>
            <!-- <origin rpy="0 0 0" xyz="0.1 0 -0.15" /> -->
            <!-- <origin rpy="0 0 0" xyz="0 0 -0" /> -->
            <geometry>
                <sphere radius="0.025" />
            </geometry>
            <material name="Grey">
                <color rgba="0.6 0.6 0.6 1" />
            </material>
        </visual>
    </link>

    <!-- Joint - back caster -->
    <joint name="joint_base_back_caster" type="fixed">
        <origin rpy="0 0 0" xyz="-0.2 0 -0.15" />
        <child link="link_back_caster" />
        <parent link="link_base" />
        <joint_properties damping="1.0" friction="0.0" />
    </joint>
    <!-- Link - back caster -->
    <link name="link_back_caster">
        <inertial>
            <mass value="0.5" />
            <origin xyz="0 0 0" rpy="0 0 0" />
            <inertia ixx="0.000125" ixy="0" ixz="0" iyy="0.000125" iyz="0" izz="0.000125"/>
        </inertial>
        <!-- Back caster support -->
        <collision>
            <!-- <origin rpy="0 0 0" xyz="-0.1 0 -0.15" /> -->
            <origin rpy="0 0 0" xyz="0 0 0" />
            <geometry>
                <sphere radius="0.025" />
            </geometry>
        </collision>
        <visual>
            <!-- <origin rpy="0 0 0" xyz="-0.1 0 -0.15" /> -->
            <origin rpy="0 0 0" xyz="0 0 0" />
            <geometry>
                <!-- <sphere radius="0.2" /> -->
                <sphere radius="0.025" />
            </geometry>
            <material name="DarkBlue">
                <color rgba="0.2 0.2 0.4 1" />
            </material>
        </visual>
        <!-- Back caster -->
        <collision>
            <!-- <origin rpy="0 0 0" xyz="-0.1 0 -0.15" /> -->
            <origin rpy="0 0 0" xyz="0 0 0" />
            <geometry>
                <sphere radius="0.025" />
            </geometry>
        </collision>
        <visual>
            <!-- <origin rpy="0 0 0" xyz="-0.1 0 -0.15" /> -->
            <origin rpy="0 0 0" xyz="0 0 0" />
            <geometry>
                <sphere radius="0.025" />
            </geometry>
            <material name="Grey">
                <color rgba="0.6 0.6 0.6 1" />
            </material>
        </visual>
    </link>


    <!-- Joint - base / left wheel -->
    <joint name="joint_base_left_wheel" type="continuous">
        <!-- <origin rpy="0 0 0" xyz="-0.5 0.3 0" /> -->
        <origin rpy="0 0 0" xyz="0.0 0.2 -0.15" />
        <child link="link_left_wheel" />
        <parent link="link_base" />
        <axis rpy="0 0 0" xyz="0 1 0" />
        <limit effort="10000" velocity="1000" />
        <joint_properties damping="1.0" friction="1.0" />
    </joint>
    <!-- Link - left wheel -->
    <link name="link_left_wheel">
        <inertial>
            <mass value="1" />
            <origin xyz="0 0 0" rpy="0 0 0" />
            <inertia ixx="0.00023125" ixy="0" ixz="0" iyy="0.00023125" iyz="0" izz="0.0003125"/>
        </inertial>
        <!-- Tires -->
        <collision>
            <!-- <origin rpy="1.5707 0 0" xyz="0.0 0.2 -0.15" /> -->
            <origin rpy="1.5707 0 0" xyz="0 0 0" />
            <geometry>
                <cylinder length="0.03" radius="0.025"/>
            </geometry>
        </collision>
        <visual>
            <!-- <origin rpy="1.5707 0 0" xyz="0.0 0.2 -0.15" /> -->
            <origin rpy="1.5707 0 0" xyz="0 0 0" />
            <geometry>
                <cylinder length="0.03" radius="0.025"/>
            </geometry>
            <material name="Black">
                <color rgba="0.1 0.1 0.1 1" />
            </material>
        </visual>
    </link>

    <!-- Joint - base / right wheel -->
    <joint name="joint_base_right_wheel" type="continuous">
        <!-- <origin rpy="0 0 0" xyz="-0.5 -0.65 0" /> -->
        <origin rpy="0 0 0" xyz="0.0 -0.2 -0.15" />
        <child link="link_right_wheel" />
        <parent link="link_base" />
        <axis rpy="0 0 0" xyz="0 1 0" />
        <limit effort="10000" velocity="1000" />
        <joint_properties damping="1.0" friction="1.0" />
    </joint>
    <!-- Link - right wheel -->
    <link name="link_right_wheel">
        <inertial>
            <mass value="1" />
            <origin xyz="0 0 0" rpy="0 0 0" />
            <inertia ixx="0.00023125" ixy="0" ixz="0" iyy="0.00023125" iyz="0" izz="0.0003125"/>
        </inertial>
        <!-- Tires -->
        <collision>
            <!-- <origin rpy="1.5707 0 0" xyz="0.0 -0.2 -0.15" /> -->
            <origin rpy="1.5707 0 0" xyz="0 0 0" />
            <geometry>
                <cylinder length="0.03" radius="0.025"/>
            </geometry>
        </collision>
        <visual>
            <!-- <origin rpy="1.5707 0 0" xyz="0.0 -0.2 -0.15" /> -->
            <origin rpy="1.5707 0 0" xyz="0 0 0" />
            <geometry>
                <cylinder length="0.03" radius="0.025"/>
            </geometry>
            <material name="Black">
                <color rgba="0.1 0.1 0.1 1" />
            </material>
        </visual>
    </link>

    <!-- Laser scan -->
    <joint name="joint_front_laser" type="fixed">
        <origin rpy="3.14159 0 0" xyz="0.25 0 0.075" />
        <child link="link_front_laser" />
        <parent link="link_base" />
        <joint_properties damping="1.0" friction="1.0" />
    </joint>
    <link name="link_front_laser">
        <inertial>
            <origin xyz="0 0 0" rpy="0 0 0" />
            <mass value="0" />
            <inertia ixx="0" ixy="0" ixz="0" iyy="0" iyz="0" izz="0"/>
        </inertial>
        <visual>
            <origin xyz="0 0 0" rpy="0 0 0" />
            <geometry>
                <!-- <box radius="0.05" length="0.02"/> -->
                <box size="0.025 0.025 0.025" />
            </geometry>
            <material name="Red">
                <color rgba="0.7 0.1 0.1 1" />
            </material>
        </visual>
        <collision>
            <origin xyz="0 0 0" rpy="0 0 0"/>
            <geometry>
                <box size="0.025 0.025 0.025" />
            </geometry>
        </collision>
    </link>

    <!-- Base footprint -->
    <joint name="joint_base_footprint" type="fixed">
        <origin rpy="0 0 0" xyz="0 0 -0.15" />
        <child link="link_base_footprint" />
        <parent link="link_base" />
        <joint_properties damping="0.0" friction="0.0" />
    </joint>
    <link name="link_base_footprint">
        <inertial>
            <origin xyz="0 0 0" rpy="0 0 0" />
            <mass value="0.0" />
            <inertia ixx="0" ixy="0" ixz="0" iyy="0" iyz="0" izz="0"/>
        </inertial>
        <visual>
            <origin xyz="0 0 0" rpy="0 0 0" />
            <geometry>
                <cylinder length="0.0" radius="0.25" />
            </geometry>
            <material name="Red">
                <color rgba="0.7 0.1 0.1 1" />
            </material>
        </visual>
        <collision>
            <origin xyz="0 0 0" rpy="0 0 0"/>
            <geometry>
                <cylinder length="0.0" radius="0.25" />
            </geometry>
        </collision>
    </link>

    <gazebo reference="link_base">
        <material>Gazebo/Black</material>
    </gazebo>

    <gazebo reference="link_front_caster">
        <material>Gazebo/Grey</material>
        <mu1>0.0<
    </gazebo>

    <gazebo reference="link_back_caster">
        <material>Gazebo/Grey</material>
    </gazebo>

    <gazebo reference="link_left_wheel">
        <material>Gazebo/Red</material>
    </gazebo>

    <gazebo reference="link_right_wheel">
        <material>Gazebo/Red</material>
    </gazebo>

    <gazebo reference="link_front_laser">
        <material>Gazebo/Orange</material>
    </gazebo>

    <!-- Differential drive plugin -->
    <gazebo>
        <plugin name="differential_drive_controller" filename="libgazebo_ros_diff_drive.so">
            <updateRate>100.0</updateRate>
            <robotNamespace>/</robotNamespace>
            <leftJoint>joint_base_left_wheel</leftJoint>
            <rightJoint>joint_base_right_wheel</rightJoint>
            <wheelSeparation>0.4</wheelSeparation>
            <wheelDiameter>0.05</wheelDiameter>
            <robotBaseFrame>link_base</robotBaseFrame>
            <torque>5</torque>
            <commandTopic>cmd_vel</commandTopic>
            <odometryTopic>odom</odometryTopic>
            <broadcastTF>false</broadcastTF>
        </plugin>
    </gazebo>

    <!-- Laser plugin -->
    <gazebo reference="link_front_laser">
        <sensor type="ray" name="head_hokuyo_sensor">
            <pose>0 0 0 0 0 0</pose>
            <visualize>true</visualize>
            <update_rate>20</update_rate>
            <ray>
                <scan>
                    <horizontal>
                        <samples>720</samples>
                        <resolution>1</resolution>
                        <min_angle>-1.570796</min_angle>
                        <max_angle>1.570796</max_angle>
                    </horizontal>
                </scan>
                <range>
                    <min>0.20</min>
                    <max>10.0</max>
                    <resolution>0.01</resolution>
                </range>
                <noise>
                    <type>gaussian</type>
                    <mean>0.0</mean>
                    <stddev>0.01</stddev>
                </noise>
            </ray>
            <plugin name="gazebo_ros_head_hokuyo_controller" filename="libgazebo_ros_laser.so">
                <topicName>scan</topicName>
                <frameName>sensor_laser</frameName>
            </plugin>
        </sensor>
    </gazebo>
</robot>
